Workbook

Sheet 2019
A1: name | B1: Male | C1: Female | D1: Total
A2: Al Jawf | B2: 17.4998 | C2: 50.797107 | D2: 28.791701
A3: Al Madinah | B3: 6.9080513 | C3: 48.585136 | D3: 18.640461
A4: Jizan | B4: 3.3191806 | C4: 42.472224 | D4: 15.209747
A5: Al Bahah | B5: 6.5059423 | C5: 41.393881 | D5: 19.775406
A6: Makkah | B6: 4.7678899 | C6: 32.049542 | D6: 12.07511
A7: Ar Riyad | B7: 5.359821 | C7: 31.148264 | D7: 12.085301
A8: `Asir | B8: 5.6622367 | C8: 30.214418 | D8: 13.722029
A9: Najran | B9: 2.0683587 | C9: 30.100911 | D9: 10.275592
A10: Ha'il | B10: 3.2985894 | C10: 24.085708 | D10: 8.1092271
A11: Ash Sharqiyah | B11: 3.7732982 | C11: 22.393609 | D11: 8.5378789
A12: Al Hudud ash Shamaliyah | B12: 2.9517145 | C12: 18.683415 | D12: 6.5899188
A13: Tabuk | B13: 2.8400792 | C13: 18.481393 | D13: 6.8327069
A14: Al Quassim | B14: 6.3383538 | C14: 0 | D14: 4.9099375
C16: =MIN(C2:C14) -> 0
C17: =MAX(C2:C14) -> 50.797107

Sheet 2022
A1: name | B1: Male | C1: Female | D1: Total
A2: Al Madinah | B2: 7.1919741 | C2: 23.161464 | D2: 12.774305
A3: Ha'il | B3: 5.4307908 | C3: 21.982126 | D3: 10.885888
A4: `Asir | B4: 5.9235326 | C4: 20.564892 | D4: 10.823243
A5: Tabuk | B5: 4.1813785 | C5: 19.790541 | D5: 8.8134617
A6: Al Jawf | B6: 4.7683766 | C6: 18.794762 | D6: 9.4517845
A7: Jizan | B7: 8.2485356 | C7: 18.601392 | D7: 11.788659
A8: Al Bahah | B8: 5.0993671 | C8: 17.773307 | D8: 9.5484749
A9: Al Hudud ash Shamaliyah | B9: 3.4934062 | C9: 16.38963 | D9: 7.9237227
A10: Najran | B10: 4.0928186 | C10: 16.200338 | D10: 8.1700451
A11: Al Quassim | B11: 4.4762639 | C11: 15.497507 | D11: 8.2074615
A12: Makkah | B12: 4.0584559 | C12: 14.003034 | D12: 7.4212069
A13: Ash Sharqiyah | B13: 3.7258291 | C13: 13.792621 | D13: 6.9666782
A14: Ar Riyad | B14: 2.9901939 | C14: 13.580417 | D14: 6.8872388
C16: =MIN(C2:C14) -> 13.580417
C17: =MAX(C2:C14) -> 23.161464

Sheet combined
A1: year | B1: region_en | C1: gender | D1: rate | E1: unemp.score
A2: 2022 | B2: Ar Riyad | C2: Male | D2: 2.9901939 | E2: =(D2-MIN($D$2:$D$14))/(MAX($D$2:$D$14)-MIN($D$2:$D$14)) -> 0
A3: 2022 | B3: Makkah | C3: Male | D3: 4.0584559 | E3: =(D3-MIN($D$2:$D$14))/(MAX($D$2:$D$14)-MIN($D$2:$D$14)) -> 0.20315568
A4: 2022 | B4: Al Madinah | C4: Male | D4: 7.1919741 | E4: =(D4-MIN($D$2:$D$14))/(MAX($D$2:$D$14)-MIN($D$2:$D$14)) -> 0.79906945
A5: 2022 | B5: Al Quassim | C5: Male | D5: 4.4762639 | E5: =(D5-MIN($D$2:$D$14))/(MAX($D$2:$D$14)-MIN($D$2:$D$14)) -> 0.2826119
A6: 2022 | B6: Ash Sharqiyah | C6: Male | D6: 3.7258291 | E6: =(D6-MIN($D$2:$D$14))/(MAX($D$2:$D$14)-MIN($D$2:$D$14)) -> 0.13989871
A7: 2022 | B7: `Asir | C7: Male | D7: 5.9235326 | E7: =(D7-MIN($D$2:$D$14))/(MAX($D$2:$D$14)-MIN($D$2:$D$14)) -> 0.55784482
A8: 2022 | B8: Tabuk | C8: Male | D8: 4.1813785 | E8: =(D8-MIN($D$2:$D$14))/(MAX($D$2:$D$14)-MIN($D$2:$D$14)) -> 0.22653236
A9: 2022 | B9: Ha'il | C9: Male | D9: 5.4307908 | E9: =(D9-MIN($D$2:$D$14))/(MAX($D$2:$D$14)-MIN($D$2:$D$14)) -> 0.46413813
A10: 2022 | B10: Al Hudud ash Shamaliyah | C10: Male | D10: 3.4934062 | E10: =(D10-MIN($D$2:$D$14))/(MAX($D$2:$D$14)-MIN($D$2:$D$14)) -> 0.095697908
A11: 2022 | B11: Jizan | C11: Male | D11: 8.2485356 | E11: =(D11-MIN($D$2:$D$14))/(MAX($D$2:$D$14)-MIN($D$2:$D$14)) -> 1
A12: 2022 | B12: Najran | C12: Male | D12: 4.0928186 | E12: =(D12-MIN($D$2:$D$14))/(MAX($D$2:$D$14)-MIN($D$2:$D$14)) -> 0.20969057
A13: 2022 | B13: Al Bahah | C13: Male | D13: 5.0993671 | E13: =(D13-MIN($D$2:$D$14))/(MAX($D$2:$D$14)-MIN($D$2:$D$14)) -> 0.40110995
A14: 2022 | B14: Al Jawf | C14: Male | D14: 4.7683766 | E14: =(D14-MIN($D$2:$D$14))/(MAX($D$2:$D$14)-MIN($D$2:$D$14)) -> 0.33816416
A15: 2022 | B15: Ar Riyad | C15: Female | D15: 13.580417 | E15: =(D15-MIN($D$15:$D$27))/(MAX($D$15:$D$27)-MIN($D$15:$D$27)) -> 0
A16: 2022 | B16: Makkah | C16: Female | D16: 14.003034 | E16: =(D16-MIN($D$15:$D$27))/(MAX($D$15:$D$27)-MIN($D$15:$D$27)) -> 0.044109755
A17: 2022 | B17: Al Madinah | C17: Female | D17: 23.161464 | E17: =(D17-MIN($D$15:$D$27))/(MAX($D$15:$D$27)-MIN($D$15:$D$27)) -> 1
A18: 2022 | B18: Al Quassim | C18: Female | D18: 15.497507 | E18: =(D18-MIN($D$15:$D$27))/(MAX($D$15:$D$27)-MIN($D$15:$D$27)) -> 0.20009199
A19: 2022 | B19: Ash Sharqiyah | C19: Female | D19: 13.792621 | E19: =(D19-MIN($D$15:$D$27))/(MAX($D$15:$D$27)-MIN($D$15:$D$27)) -> 0.022148391
A20: 2022 | B20: `Asir | C20: Female | D20: 20.564892 | E20: =(D20-MIN($D$15:$D$27))/(MAX($D$15:$D$27)-MIN($D$15:$D$27)) -> 0.72898872
A21: 2022 | B21: Tabuk | C21: Female | D21: 19.790541 | E21: =(D21-MIN($D$15:$D$27))/(MAX($D$15:$D$27)-MIN($D$15:$D$27)) -> 0.64816763
A22: 2022 | B22: Ha'il | C22: Female | D22: 21.982126 | E22: =(D22-MIN($D$15:$D$27))/(MAX($D$15:$D$27)-MIN($D$15:$D$27)) -> 0.87690932
A23: 2022 | B23: Al Hudud ash Shamaliyah | C23: Female | D23: 16.38963 | E23: =(D23-MIN($D$15:$D$27))/(MAX($D$15:$D$27)-MIN($D$15:$D$27)) -> 0.29320527
A24: 2022 | B24: Jizan | C24: Female | D24: 18.601392 | E24: =(D24-MIN($D$15:$D$27))/(MAX($D$15:$D$27)-MIN($D$15:$D$27)) -> 0.52405283
A25: 2022 | B25: Najran | C25: Female | D25: 16.200338 | E25: =(D25-MIN($D$15:$D$27))/(MAX($D$15:$D$27)-MIN($D$15:$D$27)) -> 0.27344831
A26: 2022 | B26: Al Bahah | C26: Female | D26: 17.773307 | E26: =(D26-MIN($D$15:$D$27))/(MAX($D$15:$D$27)-MIN($D$15:$D$27)) -> 0.43762333
A27: 2022 | B27: Al Jawf | C27: Female | D27: 18.794762 | E27: =(D27-MIN($D$15:$D$27))/(MAX($D$15:$D$27)-MIN($D$15:$D$27)) -> 0.54423538
A28: 2019 | B28: Ar Riyad | C28: Male | D28: 5.359821 | E28: =(D28-MIN($D$28:$D$40))/(MAX($D$28:$D$40)-MIN($D$28:$D$40)) -> 0.21329584
A29: 2019 | B29: Makkah | C29: Male | D29: 4.7678899 | E29: =(D29-MIN($D$28:$D$40))/(MAX($D$28:$D$40)-MIN($D$28:$D$40)) -> 0.17493707
A30: 2019 | B30: Al Madinah | C30: Male | D30: 6.9080513 | E30: =(D30-MIN($D$28:$D$40))/(MAX($D$28:$D$40)-MIN($D$28:$D$40)) -> 0.31362544
A31: 2019 | B31: Al Quassim | C31: Male | D31: 6.3383538 | E31: =(D31-MIN($D$28:$D$40))/(MAX($D$28:$D$40)-MIN($D$28:$D$40)) -> 0.27670746
A32: 2019 | B32: Ash Sharqiyah | C32: Male | D32: 3.7732982 | E32: =(D32-MIN($D$28:$D$40))/(MAX($D$28:$D$40)-MIN($D$28:$D$40)) -> 0.11048479
A33: 2019 | B33: `Asir | C33: Male | D33: 5.6622367 | E33: =(D33-MIN($D$28:$D$40))/(MAX($D$28:$D$40)-MIN($D$28:$D$40)) -> 0.23289321
A34: 2019 | B34: Tabuk | C34: Male | D34: 2.8400792 | E34: =(D34-MIN($D$28:$D$40))/(MAX($D$28:$D$40)-MIN($D$28:$D$40)) -> 0.050009621
A35: 2019 | B35: Ha'il | C35: Male | D35: 3.2985894 | E35: =(D35-MIN($D$28:$D$40))/(MAX($D$28:$D$40)-MIN($D$28:$D$40)) -> 0.079722344
A36: 2019 | B36: Al Hudud ash Shamaliyah | C36: Male | D36: 2.9517145 | E36: =(D36-MIN($D$28:$D$40))/(MAX($D$28:$D$40)-MIN($D$28:$D$40)) -> 0.057243895
A37: 2019 | B37: Jizan | C37: Male | D37: 3.3191806 | E37: =(D37-MIN($D$28:$D$40))/(MAX($D$28:$D$40)-MIN($D$28:$D$40)) -> 0.081056715
A38: 2019 | B38: Najran | C38: Male | D38: 2.0683587 | E38: =(D38-MIN($D$28:$D$40))/(MAX($D$28:$D$40)-MIN($D$28:$D$40)) -> 0
A39: 2019 | B39: Al Bahah | C39: Male | D39: 6.5059423 | E39: =(D39-MIN($D$28:$D$40))/(MAX($D$28:$D$40)-MIN($D$28:$D$40)) -> 0.28756767
A40: 2019 | B40: Al Jawf | C40: Male | D40: 17.4998 | E40: =(D40-MIN($D$28:$D$40))/(MAX($D$28:$D$40)-MIN($D$28:$D$40)) -> 1
...

Sheet Sheet1
C1: Unemp rate (%) | D1: Normalised | E1: Unemp rate (%) | F1: Normalised
C2: 2019 | D2: 2019 | E2: 2022 | F2: 2022
A3: Female | B3: Ar Riyad | C3: =SUMIFS(combined!$D:$D,combined!$B:$B,$B3,combined!$C:$C,$A3,combined!$A:$A,C$2) -> 31.148264 | D3: =SUMIFS(combined!$E:$E,combined!$B:$B,$B3,combined!$C:$C,$A3,combined!$A:$A,D$2) -> 0.61318972 | E3: =SUMIFS(combined!$D:$D,combined!$B:$B,$B3,combined!$C:$C,$A3,combined!$A:$A,E$2) -> 13.580417 | F3: =SUMIFS(combined!$E:$E,combined!$B:$B,$B3,combined!$C:$C,$A3,combined!$A:$A,F$2) -> 0
A4: Female | B4: Makkah | C4: =SUMIFS(combined!$D:$D,combined!$B:$B,$B4,combined!$C:$C,$A4,combined!$A:$A,C$2) -> 32.049542 | D4: =SUMIFS(combined!$E:$E,combined!$B:$B,$B4,combined!$C:$C,$A4,combined!$A:$A,D$2) -> 0.63093242 | E4: =SUMIFS(combined!$D:$D,combined!$B:$B,$B4,combined!$C:$C,$A4,combined!$A:$A,E$2) -> 14.003034 | F4: =SUMIFS(combined!$E:$E,combined!$B:$B,$B4,combined!$C:$C,$A4,combined!$A:$A,F$2) -> 0.044109755 | L4: 2019 | N4: 2022
A5: Female | B5: Ash Sharqiyah | C5: =SUMIFS(combined!$D:$D,combined!$B:$B,$B5,combined!$C:$C,$A5,combined!$A:$A,C$2) -> 22.393609 | D5: =SUMIFS(combined!$E:$E,combined!$B:$B,$B5,combined!$C:$C,$A5,combined!$A:$A,D$2) -> 0.44084418 | E5: =SUMIFS(combined!$D:$D,combined!$B:$B,$B5,combined!$C:$C,$A5,combined!$A:$A,E$2) -> 13.792621 | F5: =SUMIFS(combined!$E:$E,combined!$B:$B,$B5,combined!$C:$C,$A5,combined!$A:$A,F$2) -> 0.022148391 | L5: Unemp rate (%) | M5: Normalised | N5: Unemp rate (%) | O5: Normalised
L6: 2019 | M6: 2019 | N6: 2022 | O6: 2022
J7: Female | K7: Ar Riyad | L7: 31.148264 | M7: 0.61318972 | N7: 13.580417 | O7: 0
J8: Female | K8: Makkah | L8: 32.049542 | M8: 0.63093242 | N8: 14.003034 | O8: 0.044109755
J9: Female | K9: Ash Sharqiyah | L9: 22.393609 | M9: 0.44084418 | N9: 13.792621 | O9: 0.022148391
C13: 2019 | D13: Male | E13: 0.1803 | L13: 2019 | M13: 2022
K14: Men | L14: 0.18 | M14: 0.15
C15: 2022 | D15: Male | E15: 0.1464 | K15: Women | L15: 0.58 | M15: 0.1
K16: Total | L16: 0.32 | M16: 0.13
C17: 2019 | D17: Female | E17: 0.5829
C19: 2022 | D19: Female | E19: 0.0985
